<?xml version="1.0"?>
<robot name="visual">

  <material name="blue">
   <color rgba="0 0 0.8 1"/>
  </material>
    <material name="light_blue">
   <color rgba="0 188 212 0.3"/>
  </material>
  <material name="black">
   <color rgba="0 0 0 1"/>
  </material>
  <material name="white">
    <color rgba="1 1 1 1"/>
   </material>
 

  <link name="base_link">
   <visual>
      <geometry>
       <box size="1.5 0.2 0.2"/>
      </geometry>
	 <origin rpy="0 0 0" xyz="0 0 0.1"/>
      <material name="blue"/>
    </visual>
  </link>



 <link name="piller">
    <visual>
      <origin rpy="0 0 0" xyz="0 0 1.5"/>
      <geometry>
        <box size="0.2 0.2 3.0"/>
      </geometry>
      <material name="black"/>
    </visual>
  </link>

  <joint name="piller_joint" type="fixed">
      
    <parent link="base_link"/>
    <child link="piller"/>
    <origin rpy="0 0 0" xyz="-0.85 0 0"/>
  </joint>



 <link name="collar">
    <visual>
      <origin rpy="0 0 0" xyz="0 0 0"/>
      <geometry>
        <box size="0.3 0.3 0.3"/>
      </geometry>
      <material name="white"/>
    </visual>
  </link>

  <joint name="collar_joint" type="prismatic">
     <axis rpy="0 0 0" xyz="0 0 1"/>
    <parent link="piller"/>
    <child link="collar"/>
	<limit effort="1000.0" lower="-1" upper="1" velocity="0.5"/>
    <origin rpy="0 0 0" xyz="0 0 1.5"/>
  </joint>



<link name="link1">
    <visual>
      <origin rpy="0 0 0" xyz="0.25 0.025 0"/>
      <geometry>
        <box size="0.5 0.05 0.1"/>
      </geometry>
      <material name="blue"/>
    </visual>
  </link>

  <joint name="link1_joint" type="revolute">
    <axis xyz="0 1 0"/>
    <limit effort="1000.0" lower="-1.57075" upper="1.57075" velocity="0.5"/>
    <parent link="collar"/>
    <child link="link1"/>
    <origin rpy="0 0 0" xyz="0 0.15 0"/>
  </joint>



<link name="link2">
    <visual>
      <origin rpy="0 0 0" xyz="0.2 0.025 0"/>
      <geometry>
        <box size="0.5 0.05 0.1"/>
      </geometry>
      <material name="black"/>
    </visual>
  </link>

  <joint name="link2_joint" type="revolute">
    <axis xyz="0 1 0"/>
    <limit effort="1000.0" lower="-1.57075" upper="1.57075" velocity="0.5"/>
    <parent link="link1"/>
    <child link="link2"/>
    <origin rpy="0 0 0" xyz="0.5 0.05 0"/>
  </joint>



<link name="link3">
    <visual>
      <origin rpy="0 0 0" xyz="0.1 -0.025 0"/>
      <geometry>
        <box size="0.3 0.05 0.1"/>
      </geometry>
      <material name="blue"/>
    </visual>
  </link>

  <joint name="link3_joint" type="revolute">
    <axis xyz="0 1 0"/>
    <limit effort="1000.0" lower="-3.14" upper="3.14" velocity="0.5"/>
    <parent link="link2"/>
    <child link="link3"/>
    <origin rpy="0 0 0" xyz="0.45 0 0"/>
  </joint>



 <link name="brush_holder">
    <visual>
      <origin rpy="1.57075 0 0" xyz="0 -0.1 0"/>
      <geometry>
         <cylinder length="0.2" radius="0.05"/>
      </geometry>
      <material name="black"/>
    </visual>
  </link>

  <joint name="brush_holder_joint" type="fixed">
    <parent link="link3"/>
    <child link="brush_holder"/>
    <origin rpy="0 0 0" xyz="0.2 -0.05 0"/>
  </joint>



<link name="brush">
    <visual>
      <origin rpy="1.57075 0 0" xyz="0 0 0"/>
      <geometry>
         <cylinder length="0.1" radius="0.1"/>
      </geometry>
      <material name="white"/>
    </visual>
  </link>

  <joint name="brush_joint" type="continuous">
    <axis rpy="0 0 0" xyz="0 1 0"/>
    <parent link="brush_holder"/>
    <child link="brush"/>
    <origin rpy="0 0 0" xyz="0 -0.2 0"/>
  </joint>



 <link name="glass">
    <visual>
      <origin rpy="0 0 0" xyz="0 -0.025 1.5"/>
      <geometry>
        <box size="1.7 0.05 3.0"/>
      </geometry>
      <material name="light_blue"/>
    </visual>
  </link>

  <joint name="glass_joint" type="fixed">
    <parent link="base_link"/>
    <child link="glass"/>
    <origin rpy="0 0 0" xyz="-0.1 -0.1 0"/>
  </joint>


 </robot>
